Workbook
Name ActiveScenario: Assumptions!$H$4
Name Admin_Cost: Assumptions!$C$78
Name Alpha_Solar: Assumptions!$C$35
Name Alpha_Wind: Assumptions!$C$36
Name Batt_w1h: Assumptions!$C$47
Name Batt_w2h: Assumptions!$C$48
Name Batt_w4h: Assumptions!$C$49
Name Batt_w8h: Assumptions!$C$50
Name Batt_WACC: Assumptions!$C$53
Name Battery_RTE: Assumptions!$C$44
Name CF_Solar: Assumptions!$C$33
Name CF_Wind: Assumptions!$C$34
Name Coal_Accel: Assumptions!$C$19
Name Coal_CFe: Assumptions!$C$15
Name Coal_CFp: Assumptions!$C$16
Name Coal_Degrade: Assumptions!$C$87
Name Coal_Esc: Assumptions!$C$18
Name Coal_FOM: Assumptions!$C$84
Name Coal_Heat_Rate: Assumptions!$C$83
Name Coal_Price: Assumptions!$C$86
Name Coal_SRMC: Assumptions!$C$17
Name Coal_Start: Assumptions!$C$14
Name Coal_VOM: Assumptions!$C$85
Name Contract_Years: Assumptions!$C$72
Name Curtail_Rate: Assumptions!$C$63
Name Curtail_Thresh: Assumptions!$C$62
Name Def_Elas: Assumptions!$C$60
Name Dem_Growth: Assumptions!$C$8
Name Dem_Start: Assumptions!$C$7
Name Direct_Flow: Assumptions!$C$43
Name Divest_Rate: Assumptions!$C$73
Name Drought_Gap: Assumptions!#REF!
Name ELCC_base: Assumptions!$C$38
Name ESEM_Build_Cap: Assumptions!$C$74
Name ESEM_On: Assumptions!$C$65
Name ESEM_Start: Assumptions!$C$66
Name ESEM_WACC_Disc: Assumptions!$C$57
Name Firm_CFe: Assumptions!$C$23
Name Firm_CFp: Assumptions!$C$24
Name Firm_Cov: Assumptions!$C$69
Name Firm_Decay: Assumptions!$C$22
Name Firm_Gen_CF: Assumptions!$C$30
Name Firm_LRMC: Assumptions!$C$27
Name Firm_Sprd: Assumptions!$C$28
Name Firm_SRMC: Assumptions!$C$25
Name Firm_Start: Assumptions!$C$21
Name Firm_Tight: Assumptions!$C$29
Name Firm_VC: Assumptions!$C$26
Name Fwd_Alpha: Assumptions!#REF!
Name Fwd_k: Assumptions!$C$61
Name Gas_WACC: Assumptions!$C$56
Name Lag: Assumptions!$C$70
Name Markup_Base: Assumptions!$C$75
Name Markup_Rate: Assumptions!$C$76
Name Other_Firm: Assumptions!$C$11
Name Other_Gen: Assumptions!#REF!
Name Peak_Growth: Assumptions!$C$10
Name Peak_Start: Assumptions!$C$9
Name RE_Cov: Assumptions!$C$68
Name Recycle_Lag: Assumptions!$C$71

Sheet Assumptions
A1: ESEM Model v2 — Assumptions & Scenario Parameters
A3: Parameter | B3: Description | C3: Active value | D3: Unit | E3: Source | F3: Low | G3: High | H3: Scenario label: | I3: Base | J3: High WACC | K3: No ESEM | L3: WACC disc
A4: Scenario | B4: Active scenario number (1=Base, 2=High WACC, 3=No ESEM, 4=WACC discount) | C4: 1 | H4: =CHOOSE($C$4,"Scenario A","Scenario B","Scenario C","Scenario D") -> Scenario A
A6: 1. DEMAND & SUPPLY
A7: Dem_Start | B7: Starting annual energy demand (TWh) | C7: =CHOOSE($C$4,I7,J7,K7,L7) -> 180 | D7: TWh | E7: AEMO 2024 | F7: 160 | G7: 200 | I7: 180 | J7: 180 | K7: 180 | L7: 180
A8: Dem_Growth | B8: Annual demand growth rate | C8: =CHOOSE($C$4,I8,J8,K8,L8) -> 0.025 | D8: %/yr | E8: AEMO ISP 2024 | F8: 0.01 | G8: 0.04 | I8: 0.025 | J8: 0.025 | K8: 0.025 | L8: 0.025
A9: Peak_Start | B9: Initial peak demand | C9: =CHOOSE($C$4,I9,J9,K9,L9) -> 36 | D9: GW | E9: AEMO 2024 | F9: 30 | G9: 42 | I9: 36 | J9: 36 | K9: 36 | L9: 36
A10: Peak_Growth | B10: Annual peak demand growth rate | C10: =CHOOSE($C$4,I10,J10,K10,L10) -> 0.02 | D10: %/yr | E10: Own estimate | F10: 0.01 | G10: 0.03 | I10: 0.02 | J10: 0.02 | K10: 0.02 | L10: 0.02
A11: Other_Firm | B11: Other firm capacity (interconnectors, DSR) | C11: =CHOOSE($C$4,I11,J11,K11,L11) -> 0 | D11: GW | F11: 0 | G11: 0 | I11: 0 | J11: 0 | K11: 0 | L11: 0
A12: VRE_PrePipe | B12: Pre-pipeline VRE under construction at t=0 | C12: =CHOOSE($C$4,I12,J12,K12,L12) -> 3 | D12: GW | E12: AEMO 2024 | F12: 0 | G12: 5 | I12: 3 | J12: 3 | K12: 3 | L12: 3
A13: 2. COAL — Baseload exit trajectory
A14: Coal_Start | B14: Initial coal capacity | C14: =CHOOSE($C$4,I14,J14,K14,L14) -> 22 | D14: GW | E14: AEMO 2024 | F14: 15 | G14: 25 | I14: 22 | J14: 22 | K14: 22 | L14: 22
A15: Coal_CFe | B15: Coal energy capacity factor (annual) | C15: =CHOOSE($C$4,I15,J15,K15,L15) -> 0.45 | D15: — | E15: AEMO 2024 | F15: 0.4 | G15: 0.5 | I15: 0.45 | J15: 0.45 | K15: 0.45 | L15: 0.45
A16: Coal_CFp | B16: Coal peak capacity factor | C16: =CHOOSE($C$4,I16,J16,K16,L16) -> 0.75 | D16: — | E16: Own estimate | F16: 0.65 | G16: 0.85 | I16: 0.75 | J16: 0.75 | K16: 0.75 | L16: 0.75
A17: Coal_SRMC | B17: Coal short-run marginal cost | C17: =CHOOSE($C$4,I17,J17,K17,L17) -> 80 | D17: $/MWh | E17: AEMO 2024 | F17: 60 | G17: 120 | I17: 80 | J17: 80 | K17: 80 | L17: 80
A18: Coal_Esc | B18: Coal SRMC annual escalation | C18: =CHOOSE($C$4,I18,J18,K18,L18) -> 0.04 | D18: %/yr | E18: Own estimate | F18: 0.02 | G18: 0.07 | I18: 0.04 | J18: 0.04 | K18: 0.04 | L18: 0.04
A19: Coal_Accel | B19: Coal economic exit acceleration factor | C19: =CHOOSE($C$4,I19,J19,K19,L19) -> 0.15 | D19: — | E19: Calibrated | F19: 0.05 | G19: 0.3 | I19: 0.15 | J19: 0.15 | K19: 0.15 | L19: 0.15
A20: 3. EXISTING DISPATCHABLE FIRMING
A21: Firm_Start | B21: Initial dispatchable firm capacity (GW) | C21: =CHOOSE($C$4,I21,J21,K21,L21) -> 22 | D21: GW | E21: AEMO 2024 | F21: 15 | G21: 28 | I21: 22 | J21: 22 | K21: 22 | L21: 22
A22: Firm_Decay | B22: Annual depreciation on legacy firm fleet | C22: =CHOOSE($C$4,I22,J22,K22,L22) -> 0 | D22: %/yr | E22: Own estimate | F22: 0 | G22: 0.05 | I22: 0 | J22: 0 | K22: 0 | L22: 0
A23: Firm_CFe | B23: Firming energy capacity factor (annual dispatch) | C23: =CHOOSE($C$4,I23,J23,K23,L23) -> 0.22 | D23: — | E23: Own estimate | F23: 0.15 | G23: 0.3 | I23: 0.22 | J23: 0.22 | K23: 0.22 | L23: 0.22
A24: Firm_CFp | B24: Firming peak capacity factor (availability) | C24: =CHOOSE($C$4,I24,J24,K24,L24) -> 0.9 | D24: — | E24: Own estimate | F24: 0.8 | G24: 1 | I24: 0.9 | J24: 0.9 | K24: 0.9 | L24: 0.9
A25: Firm_SRMC | B25: Firm dispatch cost — scarcity pivot at zero firming deficit (energy-only revenue floor) | C25: =CHOOSE($C$4,I25,J25,K25,L25) -> 180 | D25: $/MWh | E25: Own estimate | F25: 120 | G25: 250 | I25: 180 | J25: 180 | K25: 180 | L25: 180
A26: Firm_VC | B26: Gas variable cost (fuel + variable O&M) | C26: =CHOOSE($C$4,I26,J26,K26,L26) -> 120 | D26: $/MWh | E26: Own estimate | F26: 90 | G26: 150 | I26: 120 | J26: 120 | K26: 120 | L26: 120
A27: Firm_LRMC | B27: Firm LRMC — BA fixed cost / (CFe x 8760) + fuel (auto-updates with Gas_WACC) | C27: ='Building assets'!B92 -> 250.49 | D27: $/MWh | E27: Building Assets R94
A28: Firm_Sprd | B28: Private firming entry spread above LRMC | C28: =CHOOSE($C$4,I28,J28,K28,L28) -> 60 | D28: $/MWh | E28: Own estimate | F28: 30 | G28: 100 | I28: 60 | J28: 60 | K28: 60 | L28: 60
A29: Firm_Tight | B29: Scarcity price exponential coefficient | C29: =CHOOSE($C$4,I29,J29,K29,L29) -> 3.5 | D29: — | E29: Calibrated | F29: 2 | G29: 5 | I29: 3.5 | J29: 3.5 | K29: 3.5 | L29: 3.5
A30: Firm_Gen_CF | B30: Baseline annual energy capacity factor for legacy firm generationises. | C30: =CHOOSE($C$4,I30,J30,K30,L30) -> 0.05 | D30: — | E30: AEMO ISP 2024 | F30: 0.03 | G30: 0.12 | I30: 0.05 | J30: 0.05 | K30: 0.05 | L30: 0.05
A32: VRE_Start | B32: Initial VRE+storage capacity | C32: =CHOOSE($C$4,I32,J32,K32,L32) -> 30 | D32: GW | E32: AEMO 2024 | F32: 22 | G32: 35 | I32: 30 | J32: 30 | K32: 30 | L32: 30
A33: CF_Solar | B33: Solar capacity factor | C33: =CHOOSE($C$4,I33,J33,K33,L33) -> 0.22 | D33: — | E33: GenCost 2024 | F33: 0.18 | G33: 0.28 | I33: 0.22 | J33: 0.22 | K33: 0.22 | L33: 0.22
A34: CF_Wind | B34: Wind capacity factor | C34: =CHOOSE($C$4,I34,J34,K34,L34) -> 0.35 | D34: — | E34: GenCost 2024 | F34: 0.3 | G34: 0.42 | I34: 0.35 | J34: 0.35 | K34: 0.35 | L34: 0.35
A35: Alpha_Solar | B35: Solar fraction of VRE portfolio | C35: =CHOOSE($C$4,I35,J35,K35,L35) -> 0.67 | D35: — | E35: Own estimate | F35: 0.5 | G35: 0.8 | I35: 0.67 | J35: 0.67 | K35: 0.67 | L35: 0.67
A36: Alpha_Wind | B36: Wind share (= 1 − Alpha_Solar) — computed | C36: =1-Alpha_Solar -> 0.33 | D36: — | E36: Computed
A37: VRE_CFE | B37: VRE+storage capacity factor | C37: =CF_Solar*Alpha_Solar+CF_Wind*Alpha_Wind -> 0.2629
A38: ELCC_base | B38: VRE effective load carrying capability at zero penetration. | C38: =CHOOSE($C$4,I38,J38,K38,L38) -> 0.15 | D38: — | E38: AEMO ISP 2024 | F38: 0.1 | G38: 0.2 | I38: 0.15 | J38: 0.15 | K38: 0.15 | L38: 0.15
A39: VRE_ELCC | B39: VRE effective load carrying capability — endogenised as ELCC_base × (1 − VRE_Share0). Falls as VRE penetration rises, consistent with AEMO ISP. At 32% share (base): ~10%. At 80% share: ~3%. | C39: =ELCC_base*(1-VRE_Share0) -> 0.0924249 | D39: — | E39: Computed — =ELCC_base×(1−VRE_Share0)
A40: VRE_Ratio | B40: VRE nameplate per kW-storage (sizing ratio) | C40: =CHOOSE($C$4,I40,J40,K40,L40) -> 3 | D40: ratio | E40: Own estimate | F40: 2 | G40: 4 | I40: 3 | J40: 3 | K40: 3 | L40: 3
A41: VRE_Sprd | B41: Private VRE entry spread above forward price | C41: =CHOOSE($C$4,I41,J41,K41,L41) -> 4 | D41: $/MWh | E41: Calibrated | F41: 2 | G41: 8 | I41: 4 | J41: 4 | K41: 4 | L41: 4
A42: VRE_Dep | B42: VRE stock annual depreciation rate | C42: =CHOOSE($C$4,I42,J42,K42,L42) -> 0 | D42: %/yr | E42: Own estimate | F42: 0 | G42: 0.03 | I42: 0 | J42: 0 | K42: 0 | L42: 0
A43: Direct_Flow | B43: VRE direct-to-load fraction (bypasses battery) | C43: =CHOOSE($C$4,I43,J43,K43,L43) -> 0.8 | D43: — | E43: Estimate | F43: 0.65 | G43: 0.9 | I43: 0.8 | J43: 0.8 | K43: 0.8 | L43: 0.8
...

Sheet Building assets
A1: BUILDING ASSETS — VRE+Storage and Firming LRMC Derivation
A2: Derives the all-in LRMC ($/MWh) of new-build VRE+storage and firming capacity from first principles. Uses GenCost 2025-26 capex trajectories, asset-specific WACCs, and a Delivered Energy Factor (DEF) to convert annual costs to $/MWh. Section C output feeds Model row 22. Section D output feeds Assumptions Firm_LRMC.
A3: All parameters are set on the Assumptions sheet. Section A shows them here for transparency. Do not edit parameters in this sheet.
A5: SECTION A — PARAMETERS (controlled from Assumptions; shown here for transparency)
A6: Financing
A7: Battery WACC | B7: =Batt_WACC -> 0.08
A8: Solar WACC | B8: =VRE_WACC_S -> 0.07
A9: Wind WACC | B9: =VRE_WACC_W -> 0.08
A10: Gas OCGT WACC | B10: =Gas_WACC -> 0.09
A12: Economic lives (yrs) [GenCost 2025-26]
A13: Battery | B13: 20
A14: Solar PV | B14: 30
A15: Wind | B15: 25
A16: Gas OCGT | B16: 25
A18: Battery replacement
A19: Cell replacement fraction of original capex | B19: 0.5
A20: Cell replacement year | B20: 12
A22: Portfolio composition
A23: VRE:storage ratio (kW VRE per kW storage) | B23: =VRE_Ratio -> 3
A24: Solar share of VRE portfolio | B24: =Alpha_Solar -> 0.67
A25: Wind share of VRE portfolio | B25: =Alpha_Wind -> 0.33
A26: Solar capacity factor | B26: =CF_Solar -> 0.22
A27: Wind capacity factor | B27: =CF_Wind -> 0.35
A28: Battery round-trip efficiency | B28: =Battery_RTE -> 0.9
A29: Direct-to-load fraction (bypasses storage) | B29: =Direct_Flow -> 0.8
A31: Battery duration weights (set on Assumptions; sum must = 1)
A32: w_1h | B32: =Batt_w1h -> 0.1
A33: w_2h | B33: =Batt_w2h -> 0.2
A34: w_4h | B34: =Batt_w4h -> 0.5
A35: w_8h | B35: =Batt_w8h -> 0.2
A36: Weight sum check | B36: =IF(ABS(B32+B33+B34+B35-1)<0.001,"check!","verify battery") -> check!
A37: Weighted avg duration (hrs) | B37: =1*B32+2*B33+4*B34+8*B35 -> 4.1
A38: Firming dispatch
A39: Firm dispatch CF (Firm_CFe) | B39: =Firm_CFe -> 0.22
A40: Firm variable cost $/MWh (fuel + var O&M) | B40: =Firm_VC -> 120
A42: SECTION B — CAPEX REFERENCE DATA (GenCost 2025-26, Current Policies scenario, 2025-26 $A)
A43: Source: Graham, P. and Hayward, J. 2025, GenCost 2025-26: Consultation draft, CSIRO, Australia. Appendix Table B.1.
A44: Year (model index t) | B44: =Model!C2 -> 0 | C44: =Model!D2 -> 1 | D44: =Model!E2 -> 2 | E44: =Model!F2 -> 3 | F44: =Model!G2 -> 4 | G44: =Model!H2 -> 5 | H44: =Model!I2 -> 6 | I44: =Model!J2 -> 7 | ... AA44: =Model!AB2 -> 25
A45: VRE+Storage capex ($/kW of nameplate capacity for each technology)
A46: 1h battery ($/kW) | B46: 760 | C46: 747 | D46: 740 | E46: 734 | F46: 717 | G46: 698 | H46: 689 | I46: 676 | J46: 647 | K46: 627 | L46: 611 | M46: 597 | N46: 585 | O46: 573 | P46: 568 | Q46: 562 | R46: 558 | S46: 555 | T46: 552 | U46: 550 | V46: 548 | W46: 547 | X46: 545 | Y46: 541 | Z46: 537 | AA46: 538
...

Sheet Baseline
A1: ESEM Baseline — No ESEM, No Government Intervention [market dynamics identical to Model, ESEM rows = 0]
A2: Year index (t) | B2: Unit: years from base | C2: → | D2: 0 | E2: 1 | F2: 2 | G2: 3 | H2: 4 | I2: 5 | J2: 6 | K2: 7 | L2: 8 | M2: 9 | N2: 10 | O2: 11 | P2: 12 | Q2: 13 | R2: 14 | S2: 15 | T2: 16 | U2: 17 | V2: 18 | W2: 19 | X2: 20 | Y2: 21 | Z2: 22 | AA2: 23 | AB2: 24 | AC2: 25
A3: Year label | D3: Year 1 | E3: Year 2 | F3: Year 3 | G3: Year 4 | H3: Year 5 | I3: Year 6 | J3: Year 7 | K3: Year 8 | L3: Year 9 | M3: Year 10 | N3: Year 11 | O3: Year 12 | P3: Year 13 | Q3: Year 14 | R3: Year 15 | S3: Year 16 | T3: Year 17 | U3: Year 18 | V3: Year 19 | W3: Year 20 | X3: Year 21 | Y3: Year 22 | Z3: Year 23 | AA3: Year 24 | AB3: Year 25 | AC3: Year 26
A5: STEP 1 — DEMAND
A6: Demand shock (reserved for scenario use) | B6: ±frac | D6: =0 -> 0 | E6: =0 -> 0 | F6: =0 -> 0 | G6: =0 -> 0 | H6: =0 -> 0 | I6: =0 -> 0 | J6: =0 -> 0 | K6: =0 -> 0 | ... AC6: =0 -> 0
A7: Supply shock (reserved for scenario use) | B7: ±frac | D7: =0 -> 0 | E7: =0 -> 0 | F7: =0 -> 0 | G7: =0 -> 0 | H7: =0 -> 0 | I7: =0 -> 0 | J7: =0 -> 0 | K7: =0 -> 0 | ... AC7: =0 -> 0
A8: Base energy demand — grows at Dem_Growth%/yr from Dem_Start (TWh) | B8: TWh | D8: =Dem_Start -> 180 | E8: =Dem_Start*(1+Dem_Growth)^E2 -> 184.5 | F8: =Dem_Start*(1+Dem_Growth)^F2 -> 189.1125 | G8: =Dem_Start*(1+Dem_Growth)^G2 -> 193.84031 | H8: =Dem_Start*(1+Dem_Growth)^H2 -> 198.68632 | I8: =Dem_Start*(1+Dem_Growth)^I2 -> 203.65348 | J8: =Dem_Start*(1+Dem_Growth)^J2 -> 208.74482 | K8: =Dem_Start*(1+Dem_Growth)^K2 -> 213.96344 | L8: =Dem_Start*(1+Dem_Growth)^L2 -> 219.31252 | ... AC8: =Dem_Start*(1+Dem_Growth)^AC2 -> 333.70994
A9: Effective energy demand — base × demand shock multiplier (TWh) | B9: TWh | C9: R6 demand shock is 0 in base case. Scenarios can inject a step-change in demand. | D9: =D8 -> 180 | E9: =E8*(1+E6) -> 184.5 | F9: =F8*(1+F6) -> 189.1125 | G9: =G8*(1+G6) -> 193.84031 | H9: =H8*(1+H6) -> 198.68632 | I9: =I8*(1+I6) -> 203.65348 | J9: =J8*(1+J6) -> 208.74482 | K9: =K8*(1+K6) -> 213.96344 | L9: =L8*(1+L6) -> 219.31252 | ... AC9: =AC8*(1+AC6) -> 333.70994
A10: Base peak demand — grows at Peak_Growth%/yr from Peak_Start (GW) | B10: GW | D10: =Peak_Start -> 36 | E10: =Peak_Start*(1+Peak_Growth)^E2 -> 36.72 | F10: =Peak_Start*(1+Peak_Growth)^F2 -> 37.4544 | G10: =Peak_Start*(1+Peak_Growth)^G2 -> 38.203488 | H10: =Peak_Start*(1+Peak_Growth)^H2 -> 38.967558 | I10: =Peak_Start*(1+Peak_Growth)^I2 -> 39.746909 | J10: =Peak_Start*(1+Peak_Growth)^J2 -> 40.541847 | K10: =Peak_Start*(1+Peak_Growth)^K2 -> 41.352684 | L10: =Peak_Start*(1+Peak_Growth)^L2 -> 42.179738 | ... AC10: =Peak_Start*(1+Peak_Growth)^AC2 -> 59.061816
A11: Effective peak demand — used for firming adequacy test in R30 (GW) | B11: GW | C11: Firming adequacy: total firm capacity ≥ peak demand. Deficit triggers ESEM firming contracts. | D11: =D10 -> 36 | E11: =E10*(1+E6) -> 36.72 | F11: =F10*(1+F6) -> 37.4544 | G11: =G10*(1+G6) -> 38.203488 | H11: =H10*(1+H6) -> 38.967558 | I11: =I10*(1+I6) -> 39.746909 | J11: =J10*(1+J6) -> 40.541847 | K11: =K10*(1+K6) -> 41.352684 | L11: =L10*(1+L6) -> 42.179738 | ... AC11: =AC10*(1+AC6) -> 59.061816
A12: STEP 2A — COAL
A13: Coal SRMC — short-run dispatch cost, escalated for carbon over time ($/MWh) | B13: $/MWh | C13: As carbon cost rises, coal SRMC rises. When WS falls below coal SRMC, coal is uneconomic → retires. | D13: =Coal_SRMC -> 80 | E13: =Coal_SRMC*(1+Coal_Esc)^E2 -> 83.2 | F13: =Coal_SRMC*(1+Coal_Esc)^F2 -> 86.528 | G13: =Coal_SRMC*(1+Coal_Esc)^G2 -> 89.98912 | H13: =Coal_SRMC*(1+Coal_Esc)^H2 -> 93.588685 | I13: =Coal_SRMC*(1+Coal_Esc)^I2 -> 97.332232 | J13: =Coal_SRMC*(1+Coal_Esc)^J2 -> 101.22552 | K13: =Coal_SRMC*(1+Coal_Esc)^K2 -> 105.27454 | L13: =Coal_SRMC*(1+Coal_Esc)^L2 -> 109.48552 | ... AC13: =Coal_SRMC*(1+Coal_Esc)^AC2 -> 213.26691
A14: Coal capacity — retires when WS stays below coal SRMC (GW) | B14: GW | C14: Retirement rate = Coal_Accel × max(0, (SRMC−WS)/SRMC). Faster retirement when WS is deeply below SRMC. | D14: =Coal_Start -> 22 | E14: =MAX(0,D14*(1-Coal_Accel*MAX(0,(D13-D27)/D13))) -> 18.7 | F14: =MAX(0,E14*(1-Coal_Accel*MAX(0,(E13-E27)/E13))) -> #REF! | G14: =MAX(0,F14*(1-Coal_Accel*MAX(0,(F13-F27)/F13))) -> #REF! | H14: =MAX(0,G14*(1-Coal_Accel*MAX(0,(G13-G27)/G13))) -> #REF! | I14: =MAX(0,H14*(1-Coal_Accel*MAX(0,(H13-H27)/H13))) -> #REF! | J14: =MAX(0,I14*(1-Coal_Accel*MAX(0,(I13-I27)/I13))) -> #REF! | K14: =MAX(0,J14*(1-Coal_Accel*MAX(0,(J13-J27)/J13))) -> #REF! | L14: =MAX(0,K14*(1-Coal_Accel*MAX(0,(K13-K27)/K13))) -> #REF! | ... AC14: =MAX(0,AB14*(1-Coal_Accel*MAX(0,(AB13-AB27)/AB13))) -> #REF!
A15: Coal generation — capacity × coal capacity factor × 8760 hrs (TWh) | B15: TWh | D15: =D14*Coal_CFe*8.76 -> 86.724 | E15: =E14*Coal_CFe*8.76*(1+E7) -> 73.7154 | F15: =F14*Coal_CFe*8.76*(1+F7) -> #REF! | G15: =G14*Coal_CFe*8.76*(1+G7) -> #REF! | H15: =H14*Coal_CFe*8.76*(1+H7) -> #REF! | I15: =I14*Coal_CFe*8.76*(1+I7) -> #REF! | J15: =J14*Coal_CFe*8.76*(1+J7) -> #REF! | K15: =K14*Coal_CFe*8.76*(1+K7) -> #REF! | L15: =L14*Coal_CFe*8.76*(1+L7) -> #REF! | ... AC15: =AC14*Coal_CFe*8.76*(1+AC7) -> #REF!
A16: Coal peak availability — capacity × peak CF (used in firming balance R30) (GW) | B16: GW | D16: =D14*Coal_CFp -> 16.5 | E16: =E14*Coal_CFp -> 14.025 | F16: =F14*Coal_CFp -> #REF! | G16: =G14*Coal_CFp -> #REF! | H16: =H14*Coal_CFp -> #REF! | I16: =I14*Coal_CFp -> #REF! | J16: =J14*Coal_CFp -> #REF! | K16: =K14*Coal_CFp -> #REF! | ... AC16: =AC14*Coal_CFp -> #REF!
A17: STEP 2B — LEGACY DISPATCHABLE FIRMING
A18: Legacy firm capacity — existing gas/hydro/diesel decaying at Firm_Decay%/yr (GW) | B18: GW | C18: Exponential decay = asset ageing + economic exit. No retirement trigger — legacy firm retires on schedule. ESEM firming contracts (R44) replace this as it disappears. | D18: =Firm_Start -> 22 | E18: =Firm_Start*(1-Firm_Decay)^E2 -> 22 | F18: =Firm_Start*(1-Firm_Decay)^F2 -> 22 | G18: =Firm_Start*(1-Firm_Decay)^G2 -> 22 | H18: =Firm_Start*(1-Firm_Decay)^H2 -> 22 | I18: =Firm_Start*(1-Firm_Decay)^I2 -> 22 | J18: =Firm_Start*(1-Firm_Decay)^J2 -> 22 | K18: =Firm_Start*(1-Firm_Decay)^K2 -> 22 | L18: =Firm_Start*(1-Firm_Decay)^L2 -> 22 | ... AC18: =Firm_Start*(1-Firm_Decay)^AC2 -> 22
A19: Legacy firm peak availability — feeds the firming adequacy test in R30 (GW) | B19: GW | D19: =D18*Firm_CFp -> 19.8 | E19: =E18*Firm_CFp -> 19.8 | F19: =F18*Firm_CFp -> 19.8 | G19: =G18*Firm_CFp -> 19.8 | H19: =H18*Firm_CFp -> 19.8 | I19: =I18*Firm_CFp -> 19.8 | J19: =J18*Firm_CFp -> 19.8 | K19: =K18*Firm_CFp -> 19.8 | ... AC19: =AC18*Firm_CFp -> 19.8
A20: Legacy firm generation — energy output at dispatch CF (TWh) | B20: TWh | D20: =D18*Firm_CFe*8.76 -> 42.3984 | E20: =E18*Firm_CFe*8.76 -> 42.3984 | F20: =F18*Firm_CFe*8.76 -> 42.3984 | G20: =G18*Firm_CFe*8.76 -> 42.3984 | H20: =H18*Firm_CFe*8.76 -> 42.3984 | I20: =I18*Firm_CFe*8.76 -> 42.3984 | J20: =J18*Firm_CFe*8.76 -> 42.3984 | K20: =K18*Firm_CFe*8.76 -> 42.3984 | ... AC20: =AC18*Firm_CFe*8.76 -> 42.3984
A21: STEP 2C — VRE + STORAGE
A22: VRE+Storage LRMC ($/MWh) — from Building Assets R78 | B22: $/MWh | D22: =IFERROR('Building assets'!B79,0) -> 0 | E22: =IFERROR('Building assets'!C79,0) -> 0 | F22: =IFERROR('Building assets'!D79,0) -> 0 | G22: =IFERROR('Building assets'!E79,0) -> 0 | H22: =IFERROR('Building assets'!F79,0) -> 0 | I22: =IFERROR('Building assets'!G79,0) -> 0 | J22: =IFERROR('Building assets'!H79,0) -> 0 | K22: =IFERROR('Building assets'!I79,0) -> 0 | ... AC22: =IFERROR('Building assets'!AA79,0) -> 0
A23: VRE+Storage online — existing + pipeline + ESEM stock + private stock (GW) | B23: GW | C23: VRE_Start = existing fleet. VRE_PrePipe = committed pipeline (phasing in over Lag yrs). R43 = ESEM-contracted stock (online after Lag). R40 = private merchant stock. | D23: =VRE_Start+VRE_PrePipe+D43+D40 -> 33 | E23: =VRE_Start+VRE_PrePipe*MIN(E2,Lag)+E43+E40 -> #REF! | F23: =VRE_Start+VRE_PrePipe*MIN(F2,Lag)+F43+F40 -> #REF! | G23: =VRE_Start+VRE_PrePipe*MIN(G2,Lag)+G43+G40 -> #REF! | H23: =VRE_Start+VRE_PrePipe*MIN(H2,Lag)+H43+H40 -> #REF! | I23: =VRE_Start+VRE_PrePipe*MIN(I2,Lag)+I43+I40 -> #REF! | J23: =VRE_Start+VRE_PrePipe*MIN(J2,Lag)+J43+J40 -> #REF! | K23: =VRE_Start+VRE_PrePipe*MIN(K2,Lag)+K43+K40 -> #REF! | L23: =VRE_Start+VRE_PrePipe*MIN(L2,Lag)+L43+L40 -> #REF! | ... AC23: =VRE_Start+VRE_PrePipe*MIN(AC2,Lag)+AC43+AC40 -> #REF!
A24: VRE+Storage generation — online GW × CF × 8760 × (1−curtailment) (TWh) | B24: TWh | C24: Curtailment (R28) reduces gross generation when VRE share exceeds Curtail_Thresh. At 60% VRE share: zero curtailment. At 80%: (0.80−0.60)×0.25 = 5% of gross generation lost. Supply shock (R7) scales net generation for scenario use. | D24: =D23*VRE_CFe*8.76*(1-D28) -> 75.999132 | E24: =E23*VRE_CFe*8.76*(1-E28)*(1+E7) -> #REF! | F24: =F23*VRE_CFe*8.76*(1-F28)*(1+F7) -> #REF! | G24: =G23*VRE_CFe*8.76*(1-G28)*(1+G7) -> #REF! | H24: =H23*VRE_CFe*8.76*(1-H28)*(1+H7) -> #REF! | I24: =I23*VRE_CFe*8.76*(1-I28)*(1+I7) -> #REF! | J24: =J23*VRE_CFe*8.76*(1-J28)*(1+J7) -> #REF! | K24: =K23*VRE_CFe*8.76*(1-K28)*(1+K7) -> #REF! | L24: =L23*VRE_CFe*8.76*(1-L28)*(1+L7) -> #REF! | ... AC24: =AC23*VRE_CFe*8.76*(1-AC28)*(1+AC7) -> #REF!
A25: STEP 3 — PRICE FORMATION
A26: Energy balance — (coal + VRE + other) minus demand; surplus +ve, deficit -ve (TWh) | B26: TWh | C26: The key supply-demand signal. Surplus pushes WS below LRMC. Deficit pushes WS above LRMC. Other_Gen = hydro/nuclear/geothermal (fixed exogenous input). | D26: =D15+D24+Other_Gen-D9 -> #REF! | E26: =E15+E24+Other_Gen-E9 -> #REF! | F26: =F15+F24+Other_Gen-F9 -> #REF! | G26: =G15+G24+Other_Gen-G9 -> #REF! | H26: =H15+H24+Other_Gen-H9 -> #REF! | I26: =I15+I24+Other_Gen-I9 -> #REF! | J26: =J15+J24+Other_Gen-J9 -> #REF! | K26: =K15+K24+Other_Gen-K9 -> #REF! | ... AC26: =AC15+AC24+Other_Gen-AC9 -> #REF!
A27: Average wholesale spot price ($/MWh) — pivots around LRMC | B27: $/MWh | C27: Pivot = LRMC. Surplus→WS<LRMC (merit order). Deficit→WS>LRMC (investment signal). No coal ceiling. | D27: =D22 -> 0 | E27: =E22*EXP(IF(D26>=0,-Surp_Elas,Def_Elas)*ABS(D26/D9)) -> #REF! | F27: =F22*EXP(IF(E26>=0,-Surp_Elas,Def_Elas)*ABS(E26/E9)) -> #REF! | G27: =G22*EXP(IF(F26>=0,-Surp_Elas,Def_Elas)*ABS(F26/F9)) -> #REF! | H27: =H22*EXP(IF(G26>=0,-Surp_Elas,Def_Elas)*ABS(G26/G9)) -> #REF! | I27: =I22*EXP(IF(H26>=0,-Surp_Elas,Def_Elas)*ABS(H26/H9)) -> #REF! | J27: =J22*EXP(IF(I26>=0,-Surp_Elas,Def_Elas)*ABS(I26/I9)) -> #REF! | K27: =K22*EXP(IF(J26>=0,-Surp_Elas,Def_Elas)*ABS(J26/J9)) -> #REF! | L27: =L22*EXP(IF(K26>=0,-Surp_Elas,Def_Elas)*ABS(K26/K9)) -> #REF! | ... AC27: =AC22*EXP(IF(AB26>=0,-Surp_Elas,Def_Elas)*ABS(AB26/AB9)) -> #REF!
A28: VRE curtailment fraction — share of gross generation lost when VRE floods grid (hidden intermediate) | B28: — | C28: Uses prior-year VRE share (R36) to avoid circular reference. Zero until VRE share crosses Curtail_Thresh (~60%). Grows linearly with penetration above threshold. Feeds R24 generation. | D28: =0 -> 0 | E28: =MAX(0,(D36-Curtail_Thresh)*Curtail_Rate) -> 0.00575751 | F28: =MAX(0,(E36-Curtail_Thresh)*Curtail_Rate) -> #REF! | G28: =MAX(0,(F36-Curtail_Thresh)*Curtail_Rate) -> #REF! | H28: =MAX(0,(G36-Curtail_Thresh)*Curtail_Rate) -> #REF! | I28: =MAX(0,(H36-Curtail_Thresh)*Curtail_Rate) -> #REF! | J28: =MAX(0,(I36-Curtail_Thresh)*Curtail_Rate) -> #REF! | K28: =MAX(0,(J36-Curtail_Thresh)*Curtail_Rate) -> #REF! | L28: =MAX(0,(K36-Curtail_Thresh)*Curtail_Rate) -> #REF! | ... AC28: =MAX(0,(AB36-Curtail_Thresh)*Curtail_Rate) -> #REF!
A29: Forward price — weighted average of LRMC and spot (investment signal, $/MWh) | B29: $/MWh | C29: Private VRE entry (R37) triggered when fwd > LRMC. Fwd_Alpha weights current LRMC vs current spot. Higher Fwd_Alpha = more forward-looking investors (weight on long-run cost over short-run price). | D29: =Fwd_Alpha*D22+(1-Fwd_Alpha)*D27 -> #REF! | E29: =Fwd_Alpha*E22+(1-Fwd_Alpha)*E27 -> #REF! | F29: =Fwd_Alpha*F22+(1-Fwd_Alpha)*F27 -> #REF! | G29: =Fwd_Alpha*G22+(1-Fwd_Alpha)*G27 -> #REF! | H29: =Fwd_Alpha*H22+(1-Fwd_Alpha)*H27 -> #REF! | I29: =Fwd_Alpha*I22+(1-Fwd_Alpha)*I27 -> #REF! | J29: =Fwd_Alpha*J22+(1-Fwd_Alpha)*J27 -> #REF! | K29: =Fwd_Alpha*K22+(1-Fwd_Alpha)*K27 -> #REF! | ... AC29: =Fwd_Alpha*AC22+(1-Fwd_Alpha)*AC27 -> #REF!
A30: Firming balance — total firm peak availability minus peak demand; +ve = surplus (GW) | B30: GW | C30: All sources in available GW (×CFp). R16=coal×CFp, R19=legacy×CFp already applied. ESEM stock ({p}44) and private firm ({p}51) multiplied by Firm_CFp here. Prior-year lag on both avoids circular reference and is physically realistic (new capacity cannot contribute to adequacy in its first year). | D30: =D16+D19+D44*Firm_CFp+D23*VRE_ELCC+Other_Firm-D11 -> 3.3500217 | E30: =E16+E19+D44*Firm_CFp+D51*Firm_CFp+E23*VRE_ELCC+Other_Firm-E11 -> #REF! | F30: =F16+F19+E44*Firm_CFp+E51*Firm_CFp+F23*VRE_ELCC+Other_Firm-F11 -> #REF! | G30: =G16+G19+F44*Firm_CFp+F51*Firm_CFp+G23*VRE_ELCC+Other_Firm-G11 -> #REF! | H30: =H16+H19+G44*Firm_CFp+G51*Firm_CFp+H23*VRE_ELCC+Other_Firm-H11 -> #REF! | I30: =I16+I19+H44*Firm_CFp+H51*Firm_CFp+I23*VRE_ELCC+Other_Firm-I11 -> #REF! | J30: =J16+J19+I44*Firm_CFp+I51*Firm_CFp+J23*VRE_ELCC+Other_Firm-J11 -> #REF! | K30: =K16+K19+J44*Firm_CFp+J51*Firm_CFp+K23*VRE_ELCC+Other_Firm-K11 -> #REF! | L30: =L16+L19+K44*Firm_CFp+K51*Firm_CFp+L23*VRE_ELCC+Other_Firm-L11 -> #REF! | ... AC30: =AC16+AC19+AB44*Firm_CFp+AB51*Firm_CFp+AC23*VRE_ELCC+Other_Firm-AC11 -> #REF!
A31: Firming deficit fraction — max(0, deficit/peak); zero when firm capacity is adequate | B31: — | C31: Input to scarcity formula R32. As firm capacity retires (R18/R16) faster than ESEM replaces it, deficit rises → scarcity rises → private firm investment signal strengthens. | D31: =MAX(0,-D30/D11) -> 0 | E31: =MAX(0,-E30/E11) -> #REF! | F31: =MAX(0,-F30/F11) -> #REF! | G31: =MAX(0,-G30/G11) -> #REF! | H31: =MAX(0,-H30/H11) -> #REF! | I31: =MAX(0,-I30/I11) -> #REF! | J31: =MAX(0,-J30/J11) -> #REF! | K31: =MAX(0,-K30/K11) -> #REF! | ... AC31: =MAX(0,-AC30/AC11) -> #REF!
A32: Scarcity price — pivots around Firm_SRMC (dispatch cost); rises toward Firm_LRMC as firming tightens ($/MWh) | B32: $/MWh | C32: Pivot = Firm_SRMC (energy-only dispatch cost, ~$180). At zero deficit: scarcity=Firm_SRMC < Firm_LRMC → "missing money" gap. Private firm entry (R50) triggered only when scarcity rises above Firm_LRMC (~8% deficit). ESEM cap payment (R57) bridges Firm_SRMC→Firm_LRMC to attract investment before the grid is that tight. | D32: =Firm_SRMC*EXP(Firm_Tight*D31) -> 180 | E32: =Firm_SRMC*EXP(Firm_Tight*E31) -> #REF! | F32: =Firm_SRMC*EXP(Firm_Tight*F31) -> #REF! | G32: =Firm_SRMC*EXP(Firm_Tight*G31) -> #REF! | H32: =Firm_SRMC*EXP(Firm_Tight*H31) -> #REF! | I32: =Firm_SRMC*EXP(Firm_Tight*I31) -> #REF! | J32: =Firm_SRMC*EXP(Firm_Tight*J31) -> #REF! | K32: =Firm_SRMC*EXP(Firm_Tight*K31) -> #REF! | ... AC32: =Firm_SRMC*EXP(Firm_Tight*AC31) -> #REF!
A33: STEP 4 — MARKET ENTRY
A34: VRE target share of demand — linear ramp from VRE_Share0 to VRE_ShareT over 25 yrs | B34: — | C34: Policy target: society wants VRE to supply VRE_ShareT% of energy by yr 25. ESEM fills the gap between target and what private investors will build. | D34: =VRE_Share0+(VRE_ShareT-VRE_Share0)/25*D2 -> 0.383834 | E34: =VRE_Share0+(VRE_ShareT-VRE_Share0)/25*E2 -> 0.40848064 | F34: =VRE_Share0+(VRE_ShareT-VRE_Share0)/25*F2 -> 0.43312728 | G34: =VRE_Share0+(VRE_ShareT-VRE_Share0)/25*G2 -> 0.45777392 | H34: =VRE_Share0+(VRE_ShareT-VRE_Share0)/25*H2 -> 0.48242056 | I34: =VRE_Share0+(VRE_ShareT-VRE_Share0)/25*I2 -> 0.5070672 | J34: =VRE_Share0+(VRE_ShareT-VRE_Share0)/25*J2 -> 0.53171384 | K34: =VRE_Share0+(VRE_ShareT-VRE_Share0)/25*K2 -> 0.55636048 | ... AC34: =VRE_Share0+(VRE_ShareT-VRE_Share0)/25*AC2 -> 1
A35: VRE target capacity implied by share × demand ÷ (CF × 8760) (GW) | B35: GW | C35: Converts target TWh share into required GW of installed capacity at the blended VRE capacity factor. | D35: =D34*D9/(VRE_CFe*8.76) -> 30 | E35: =E34*E9/(VRE_CFe*8.76) -> 32.72451 | F35: =F34*F9/(VRE_CFe*8.76) -> 35.566496 | G35: =G34*G9/(VRE_CFe*8.76) -> 38.530128 | H35: =H34*H9/(VRE_CFe*8.76) -> 41.619713 | I35: =I34*I9/(VRE_CFe*8.76) -> 44.839696 | J35: =J34*J9/(VRE_CFe*8.76) -> 48.194665 | K35: =K34*K9/(VRE_CFe*8.76) -> 51.689359 | ... AC35: =AC34*AC9/(VRE_CFe*8.76) -> 144.90202
A36: Current VRE share of demand — actual VRE TWh ÷ demand TWh | B36: — | C36: Used in checks sheet. If this exceeds VRE target (R34) ESEM contracts nothing — private market leading. | D36: =IF(D9>0,D24/D9,0) -> 0.4222174 | E36: =IF(E9>0,E24/E9,0) -> #REF! | F36: =IF(F9>0,F24/F9,0) -> #REF! | G36: =IF(G9>0,G24/G9,0) -> #REF! | H36: =IF(H9>0,H24/H9,0) -> #REF! | I36: =IF(I9>0,I24/I9,0) -> #REF! | J36: =IF(J9>0,J24/J9,0) -> #REF! | K36: =IF(K9>0,K24/K9,0) -> #REF! | ... AC36: =IF(AC9>0,AC24/AC9,0) -> #REF!
A37: Private VRE build — linear supply curve: GW/yr per $/MWh above LRMC (GW/yr) | B37: GW/yr | C37: VRE_Sprd = spread required to attract investment above LRMC. When fwd = LRMC: zero private build. When fwd > LRMC: build accelerates linearly. No ESEM needed if private market fills the gap first. | D37: =MAX(0,(D29-D22)/VRE_Sprd) -> #REF! | E37: =MAX(0,(E29-E22)/VRE_Sprd) -> #REF! | F37: =MAX(0,(F29-F22)/VRE_Sprd) -> #REF! | G37: =MAX(0,(G29-G22)/VRE_Sprd) -> #REF! | H37: =MAX(0,(H29-H22)/VRE_Sprd) -> #REF! | I37: =MAX(0,(I29-I22)/VRE_Sprd) -> #REF! | J37: =MAX(0,(J29-J22)/VRE_Sprd) -> #REF! | K37: =MAX(0,(K29-K22)/VRE_Sprd) -> #REF! | ... AC37: =MAX(0,(AC29-AC22)/VRE_Sprd) -> #REF!
A38: ESEM VRE contracted — covers RE_Cov fraction of shortfall to target, per year (GW/yr) | B38: GW/yr | C38: Contracts signed now; plants online after Lag years. Yr1: prior VRE = VRE_Start+PrePipe. Yr2+: uses prior-col R23 to avoid circular reference. RE_Cov < 1 leaves room for private build. Contracts: ESEM holds for Recycle_Lag yrs, then sells. | D38: 0 | E38: 0 | F38: 0 | G38: 0 | H38: 0 | I38: 0 | J38: 0 | K38: 0 | L38: 0 | M38: 0 | N38: 0 | O38: 0 | P38: 0 | Q38: 0 | R38: 0 | S38: 0 | T38: 0 | U38: 0 | V38: 0 | W38: 0 | X38: 0 | Y38: 0 | Z38: 0 | AA38: 0 | AB38: 0 | AC38: 0
A39: Firming shortfall — peak demand minus firm peak availability (GW) | B39: GW | C39: Mirrors firming balance (R30): all firm sources in available GW (×Firm_CFp). Prior-year ESEM ({p}44×CFp) and prior-year private ({p}51×CFp) avoid circular reference and correctly reflect capacity already reliably online. ESEM contracts only what legacy + existing firm stock cannot cover. | D39: =MAX(0,D11-(D16+D19+D23*VRE_ELCC+Other_Firm)) -> 0 | E39: =MAX(0,E11-(E16+E19+D44*Firm_CFp+D51*Firm_CFp+E23*VRE_ELCC+Other_Firm)) -> #REF! | F39: =MAX(0,F11-(F16+F19+E44*Firm_CFp+E51*Firm_CFp+F23*VRE_ELCC+Other_Firm)) -> #REF! | G39: =MAX(0,G11-(G16+G19+F44*Firm_CFp+F51*Firm_CFp+G23*VRE_ELCC+Other_Firm)) -> #REF! | H39: =MAX(0,H11-(H16+H19+G44*Firm_CFp+G51*Firm_CFp+H23*VRE_ELCC+Other_Firm)) -> #REF! | I39: =MAX(0,I11-(I16+I19+H44*Firm_CFp+H51*Firm_CFp+I23*VRE_ELCC+Other_Firm)) -> #REF! | J39: =MAX(0,J11-(J16+J19+I44*Firm_CFp+I51*Firm_CFp+J23*VRE_ELCC+Other_Firm)) -> #REF! | K39: =MAX(0,K11-(K16+K19+J44*Firm_CFp+J51*Firm_CFp+K23*VRE_ELCC+Other_Firm)) -> #REF! | L39: =MAX(0,L11-(L16+L19+K44*Firm_CFp+K51*Firm_CFp+L23*VRE_ELCC+Other_Firm)) -> #REF! | ... AC39: =MAX(0,AC11-(AC16+AC19+AB44*Firm_CFp+AB51*Firm_CFp+AC23*VRE_ELCC+Other_Firm)) -> #REF!
A40: Private VRE cumulative stock — builds when fwd > LRMC, depreciates at VRE_Dep (GW) | B40: GW | C40: Merchant VRE: no ESEM de-risking, builds only when market signal strong. This competes with and reduces ESEM contracted volumes (via R23 → R38). | D40: =0 -> 0 | E40: =D40*(1-VRE_Dep)+E37 -> #REF! | F40: =E40*(1-VRE_Dep)+F37 -> #REF! | G40: =F40*(1-VRE_Dep)+G37 -> #REF! | H40: =G40*(1-VRE_Dep)+H37 -> #REF! | I40: =H40*(1-VRE_Dep)+I37 -> #REF! | J40: =I40*(1-VRE_Dep)+J37 -> #REF! | K40: =J40*(1-VRE_Dep)+K37 -> #REF! | L40: =K40*(1-VRE_Dep)+L37 -> #REF! | ... AC40: =AB40*(1-VRE_Dep)+AC37 -> #REF!
A41: ESEM firming contracted — covers Firm_Cov fraction of firming shortfall (GW/yr) | B41: GW/yr | C41: ESEM signs cap contracts with firm generators → gives them revenue certainty to invest. Cap contracts then sold on to retailers (R57). Net margin feeds levy (R63). | D41: 0 | E41: 0 | F41: 0 | G41: 0 | H41: 0 | I41: 0 | J41: 0 | K41: 0 | L41: 0 | M41: 0 | N41: 0 | O41: 0 | P41: 0 | Q41: 0 | R41: 0 | S41: 0 | T41: 0 | U41: 0 | V41: 0 | W41: 0 | X41: 0 | Y41: 0 | Z41: 0 | AA41: 0 | AB41: 0 | AC41: 0
...

Sheet Model
A1: ESEM Model — Time Series Calculations [formulas only — do not edit]
A2: Year index (t) | B2: Unit: years from base | C2: 0 | D2: 1 | E2: 2 | F2: 3 | G2: 4 | H2: 5 | I2: 6 | J2: 7 | K2: 8 | L2: 9 | M2: 10 | N2: 11 | O2: 12 | P2: 13 | Q2: 14 | R2: 15 | S2: 16 | T2: 17 | U2: 18 | V2: 19 | W2: 20 | X2: 21 | Y2: 22 | Z2: 23 | AA2: 24 | AB2: 25
A3: Year label | C3: Year 1 | D3: Year 2 | E3: Year 3 | F3: Year 4 | G3: Year 5 | H3: Year 6 | I3: Year 7 | J3: Year 8 | K3: Year 9 | L3: Year 10 | M3: Year 11 | N3: Year 12 | O3: Year 13 | P3: Year 14 | Q3: Year 15 | R3: Year 16 | S3: Year 17 | T3: Year 18 | U3: Year 19 | V3: Year 20 | W3: Year 21 | X3: Year 22 | Y3: Year 23 | Z3: Year 24 | AA3: Year 25 | AB3: Year 26
A5: DEMAND
A6: Demand shock (reserved for scenario use) | B6: ±frac | C6: 0 | D6: =0 -> 0 | E6: =0 -> 0 | F6: =0 -> 0 | G6: =0 -> 0 | H6: =0 -> 0 | I6: =0 -> 0 | J6: =0 -> 0 | K6: =0 -> 0 | ... AB6: =0 -> 0
A7: Supply shock (reserved for scenario use) | B7: ±frac | C7: 0 | D7: =0 -> 0 | E7: =0 -> 0 | F7: =0 -> 0 | G7: =0 -> 0 | H7: =0 -> 0 | I7: =0 -> 0 | J7: =0 -> 0 | K7: =0 -> 0 | ... AB7: =0 -> 0
A8: Base energy demand | B8: TWh | C8: =Dem_Start -> 180 | D8: =Dem_Start*(1+Dem_Growth)^D2 -> 184.5 | E8: =Dem_Start*(1+Dem_Growth)^E2 -> 189.1125 | F8: =Dem_Start*(1+Dem_Growth)^F2 -> 193.84031 | G8: =Dem_Start*(1+Dem_Growth)^G2 -> 198.68632 | H8: =Dem_Start*(1+Dem_Growth)^H2 -> 203.65348 | I8: =Dem_Start*(1+Dem_Growth)^I2 -> 208.74482 | J8: =Dem_Start*(1+Dem_Growth)^J2 -> 213.96344 | K8: =Dem_Start*(1+Dem_Growth)^K2 -> 219.31252 | ... AB8: =Dem_Start*(1+Dem_Growth)^AB2 -> 333.70994
A9: Effective energy demand | B9: TWh | C9: =C8 -> 180 | D9: =D8*(1+D6) -> 184.5 | E9: =E8*(1+E6) -> 189.1125 | F9: =F8*(1+F6) -> 193.84031 | G9: =G8*(1+G6) -> 198.68632 | H9: =H8*(1+H6) -> 203.65348 | I9: =I8*(1+I6) -> 208.74482 | J9: =J8*(1+J6) -> 213.96344 | K9: =K8*(1+K6) -> 219.31252 | ... AB9: =AB8*(1+AB6) -> 333.70994
A10: Base peak demand | B10: GW | C10: =Peak_Start -> 36 | D10: =Peak_Start*(1+Peak_Growth)^D2 -> 36.72 | E10: =Peak_Start*(1+Peak_Growth)^E2 -> 37.4544 | F10: =Peak_Start*(1+Peak_Growth)^F2 -> 38.203488 | G10: =Peak_Start*(1+Peak_Growth)^G2 -> 38.967558 | H10: =Peak_Start*(1+Peak_Growth)^H2 -> 39.746909 | I10: =Peak_Start*(1+Peak_Growth)^I2 -> 40.541847 | J10: =Peak_Start*(1+Peak_Growth)^J2 -> 41.352684 | K10: =Peak_Start*(1+Peak_Growth)^K2 -> 42.179738 | ... AB10: =Peak_Start*(1+Peak_Growth)^AB2 -> 59.061816
A11: Effective peak demand | B11: GW | C11: =C10 -> 36 | D11: =D10*(1+D6) -> 36.72 | E11: =E10*(1+E6) -> 37.4544 | F11: =F10*(1+F6) -> 38.203488 | G11: =G10*(1+G6) -> 38.967558 | H11: =H10*(1+H6) -> 39.746909 | I11: =I10*(1+I6) -> 40.541847 | J11: =J10*(1+J6) -> 41.352684 | K11: =K10*(1+K6) -> 42.179738 | ... AB11: =AB10*(1+AB6) -> 59.061816
A12: COAL
A13: Coal SRMC ($/MWh) — derived from BA Section E (fuel + VOM), escalating | B13: $/MWh | C13: =IFERROR('Building assets'!B106,Coal_SRMC) -> 79.97907 | D13: =IFERROR('Building assets'!C106,Coal_SRMC) -> 82.991033 | E13: =IFERROR('Building assets'!D106,Coal_SRMC) -> 86.123474 | F13: =IFERROR('Building assets'!E106,Coal_SRMC) -> 89.381213 | G13: =IFERROR('Building assets'!F106,Coal_SRMC) -> 92.769262 | H13: =IFERROR('Building assets'!G106,Coal_SRMC) -> 96.292832 | I13: =IFERROR('Building assets'!H106,Coal_SRMC) -> 99.957345 | J13: =IFERROR('Building assets'!I106,Coal_SRMC) -> 103.76844 | ... AB13: =IFERROR('Building assets'!AA106,Coal_SRMC) -> 205.415
A14: Coal capacity | B14: GW | C14: =Coal_Start -> 22 | D14: =MAX(0,C14*(1-Coal_Accel*MAX(0,(C13-C27)/C13))) -> 22 | E14: =MAX(0,D14*(1-Coal_Accel*MAX(0,(D13-D27)/D13))) -> 22 | F14: =MAX(0,E14*(1-Coal_Accel*MAX(0,(E13-E27)/E13))) -> 22 | G14: =MAX(0,F14*(1-Coal_Accel*MAX(0,(F13-F27)/F13))) -> 22 | H14: =MAX(0,G14*(1-Coal_Accel*MAX(0,(G13-G27)/G13))) -> 22 | I14: =MAX(0,H14*(1-Coal_Accel*MAX(0,(H13-H27)/H13))) -> 22 | J14: =MAX(0,I14*(1-Coal_Accel*MAX(0,(I13-I27)/I13))) -> 22 | K14: =MAX(0,J14*(1-Coal_Accel*MAX(0,(J13-J27)/J13))) -> 21.91168 | ... AB14: =MAX(0,AA14*(1-Coal_Accel*MAX(0,(AA13-AA27)/AA13))) -> 8.0227624
A15: Coal generation (TWh) — uses time-varying CFe with reliability degradation | B15: TWh | C15: =C14*IFERROR('Building assets'!B110,Coal_CFe)*8.76 -> 86.724 | D15: =D14*IFERROR('Building assets'!C110,Coal_CFe)*8.76 -> 85.42314 | E15: =E14*IFERROR('Building assets'!D110,Coal_CFe)*8.76 -> 84.141793 | F15: =F14*IFERROR('Building assets'!E110,Coal_CFe)*8.76 -> 82.879666 | G15: =G14*IFERROR('Building assets'!F110,Coal_CFe)*8.76 -> 81.636471 | H15: =H14*IFERROR('Building assets'!G110,Coal_CFe)*8.76 -> 80.411924 | I15: =I14*IFERROR('Building assets'!H110,Coal_CFe)*8.76 -> 79.205745 | J15: =J14*IFERROR('Building assets'!I110,Coal_CFe)*8.76 -> 78.017659 | ... AB15: =AB14*IFERROR('Building assets'!AA110,Coal_CFe)*8.76 -> 21.674362
A16: Coal firming availability (GW) — uses time-varying CFp with reliability degradation | B16: GW | C16: =C14*IFERROR('Building assets'!B111,Coal_CFp) -> 16.5 | D16: =D14*IFERROR('Building assets'!C111,Coal_CFp) -> 16.2525 | E16: =E14*IFERROR('Building assets'!D111,Coal_CFp) -> 16.008712 | F16: =F14*IFERROR('Building assets'!E111,Coal_CFp) -> 15.768582 | G16: =G14*IFERROR('Building assets'!F111,Coal_CFp) -> 15.532053 | H16: =H14*IFERROR('Building assets'!G111,Coal_CFp) -> 15.299072 | I16: =I14*IFERROR('Building assets'!H111,Coal_CFp) -> 15.069586 | J16: =J14*IFERROR('Building assets'!I111,Coal_CFp) -> 14.843542 | ... AB16: =AB14*IFERROR('Building assets'!AA111,Coal_CFp) -> 4.123737
A17: LEGACY DISPATCHABLE FIRMING
A18: Legacy firm capacity | B18: GW | C18: =Firm_Start -> 22 | D18: =Firm_Start*(1-Firm_Decay)^D2 -> 22 | E18: =Firm_Start*(1-Firm_Decay)^E2 -> 22 | F18: =Firm_Start*(1-Firm_Decay)^F2 -> 22 | G18: =Firm_Start*(1-Firm_Decay)^G2 -> 22 | H18: =Firm_Start*(1-Firm_Decay)^H2 -> 22 | I18: =Firm_Start*(1-Firm_Decay)^I2 -> 22 | J18: =Firm_Start*(1-Firm_Decay)^J2 -> 22 | K18: =Firm_Start*(1-Firm_Decay)^K2 -> 22 | ... AB18: =Firm_Start*(1-Firm_Decay)^AB2 -> 22
A19: Legacy firm peak availability | B19: GW | C19: =C18*Firm_CFp -> 19.8 | D19: =D18*Firm_CFp -> 19.8 | E19: =E18*Firm_CFp -> 19.8 | F19: =F18*Firm_CFp -> 19.8 | G19: =G18*Firm_CFp -> 19.8 | H19: =H18*Firm_CFp -> 19.8 | I19: =I18*Firm_CFp -> 19.8 | J19: =J18*Firm_CFp -> 19.8 | ... AB19: =AB18*Firm_CFp -> 19.8
A20: Legacy firm generation | B20: TWh | C20: =C18*Firm_CFe*8.76 -> 42.3984 | D20: =D18*Firm_CFe*8.76 -> 42.3984 | E20: =E18*Firm_CFe*8.76 -> 42.3984 | F20: =F18*Firm_CFe*8.76 -> 42.3984 | G20: =G18*Firm_CFe*8.76 -> 42.3984 | H20: =H18*Firm_CFe*8.76 -> 42.3984 | I20: =I18*Firm_CFe*8.76 -> 42.3984 | J20: =J18*Firm_CFe*8.76 -> 42.3984 | ... AB20: =AB18*Firm_CFe*8.76 -> 42.3984
A21: VRE + STORAGE
A22: VRE+Storage LRMC (curtailment-adjusted) | B22: $/MWh | C22: =IFERROR('Building assets'!B78,0) -> 112.22814 | D22: ='Building assets'!C78/(1-MAX(0,C28)) -> 105.35894 | E22: ='Building assets'!D78/(1-MAX(0,D28)) -> 101.50142 | F22: ='Building assets'!E78/(1-MAX(0,E28)) -> 97.872068 | G22: ='Building assets'!F78/(1-MAX(0,F28)) -> 95.138254 | H22: ='Building assets'!G78/(1-MAX(0,G28)) -> 91.853257 | I22: ='Building assets'!H78/(1-MAX(0,H28)) -> 88.844946 | J22: ='Building assets'!I78/(1-MAX(0,I28)) -> 86.775365 | K22: ='Building assets'!J78/(1-MAX(0,J28)) -> 84.717968 | ... AB22: ='Building assets'!AA78/(1-MAX(0,AA28)) -> 78.824379
A23: VRE+Storage online | B23: GW | C23: =VRE_Start+VRE_PrePipe+C43+C40 -> 35 | D23: =VRE_Start+VRE_PrePipe*MIN(D2,Lag)+D43+D40 -> 36.187673 | E23: =VRE_Start+VRE_PrePipe*MIN(E2,Lag)+E43+E40 -> 41.94278 | F23: =VRE_Start+VRE_PrePipe*MIN(F2,Lag)+F43+F40 -> 44.94278 | G23: =VRE_Start+VRE_PrePipe*MIN(G2,Lag)+G43+G40 -> 44.94278 | H23: =VRE_Start+VRE_PrePipe*MIN(H2,Lag)+H43+H40 -> 47.693266 | I23: =VRE_Start+VRE_PrePipe*MIN(I2,Lag)+I43+I40 -> 50.262399 | J23: =VRE_Start+VRE_PrePipe*MIN(J2,Lag)+J43+J40 -> 53.231679 | K23: =VRE_Start+VRE_PrePipe*MIN(K2,Lag)+K43+K40 -> 56.612355 | ... AB23: =VRE_Start+VRE_PrePipe*MIN(AB2,Lag)+AB43+AB40 -> 140.48582
A24: VRE+Storage generation (curtailment-adjusted) | B24: TWh | C24: =C23*VRE_CFe*8.76*(1-C28) -> 80.60514 | D24: =D23*VRE_CFe*8.76*(1-D28)*(1+D7) -> 82.540633 | E24: =E23*VRE_CFe*8.76*(1-E28)*(1+E7) -> 95.673738 | F24: =F23*VRE_CFe*8.76*(1-F28)*(1+F7) -> 101.60812 | G24: =G23*VRE_CFe*8.76*(1-G28)*(1+G7) -> 101.32439 | H24: =H23*VRE_CFe*8.76*(1-H28)*(1+H7) -> 107.75958 | I24: =I23*VRE_CFe*8.76*(1-I28)*(1+I7) -> 113.23167 | J24: =J23*VRE_CFe*8.76*(1-J28)*(1+J7) -> 119.67617 | K24: =K23*VRE_CFe*8.76*(1-K28)*(1+K7) -> 126.94635 | ... AB24: =AB23*VRE_CFe*8.76*(1-AB28)*(1+AB7) -> 299.34219
A25: PRICE FORMATION
A26: Energy balance (TWh) — coal + VRE + total firm capacity (legacy + ESEM-contracted + private) × Firm_Gen_CF + other − demand | B26: TWh | C26: =C15+C24+(C18+C44+C50)*Firm_Gen_CF*8.76-C9 -> -3.03486 | D26: =D15+D24+(D18+D44+D50)*Firm_Gen_CF*8.76-D9 -> -6.900227 | E26: =E15+E24+(E18+E44+E50)*Firm_Gen_CF*8.76-E9 -> 0.33903056 | F26: =F15+F24+(F18+F44+F50)*Firm_Gen_CF*8.76-F9 -> 0.28347605 | G26: =G15+G24+(G18+G44+G50)*Firm_Gen_CF*8.76-G9 -> -6.0894642 | H26: =H15+H24+(H18+H44+H50)*Firm_Gen_CF*8.76-H9 -> -5.751447 | I26: =I15+I24+(I18+I44+I50)*Firm_Gen_CF*8.76-I9 -> -6.3337635 | J26: =J15+J24+(J18+J44+J50)*Firm_Gen_CF*8.76-J9 -> -6.1680261 | ... AB26: =AB15+AB24+(AB18+AB44+AB50)*Firm_Gen_CF*8.76-AB9 -> 6.8551743
A27: Average wholesale spot price | B27: $/MWh | C27: =C22 -> 112.22814 | D27: =D22*EXP(IF(C26>=0,-Surp_Elas,Def_Elas)*ABS(C26/C9)) -> 114.62601 | E27: =E22*EXP(IF(D26>=0,-Surp_Elas,Def_Elas)*ABS(D26/D9)) -> 122.37264 | F27: =F22*EXP(IF(E26>=0,-Surp_Elas,Def_Elas)*ABS(E26/E9)) -> 97.17274 | G27: =G22*EXP(IF(F26>=0,-Surp_Elas,Def_Elas)*ABS(F26/F9)) -> 94.58335 | H27: =H22*EXP(IF(G26>=0,-Surp_Elas,Def_Elas)*ABS(G26/G9)) -> 107.06493 | I27: =I22*EXP(IF(H26>=0,-Surp_Elas,Def_Elas)*ABS(H26/H9)) -> 102.31941 | J27: =J22*EXP(IF(I26>=0,-Surp_Elas,Def_Elas)*ABS(I26/I9)) -> 100.99121 | K27: =K22*EXP(IF(J26>=0,-Surp_Elas,Def_Elas)*ABS(J26/J9)) -> 97.852878 | ... AB27: =AB22*EXP(IF(AA26>=0,-Surp_Elas,Def_Elas)*ABS(AA26/AA9)) -> 74.212876 | AC27: =AVERAGE(C27:AB27) -> 92.877016
A28: VRE curtailment fraction | B28: — | C28: =0 -> 0 | D28: =MAX(0,(C36-Curtail_Thresh)*Curtail_Rate) -> 0.00959585 | E28: =MAX(0,(D36-Curtail_Thresh)*Curtail_Rate) -> 0.0095311057 | F28: =MAX(0,(E36-Curtail_Thresh)*Curtail_Rate) -> 0.018311267 | G28: =MAX(0,(F36-Curtail_Thresh)*Curtail_Rate) -> 0.021052602 | H28: =MAX(0,(G36-Curtail_Thresh)*Curtail_Rate) -> 0.018920643 | I28: =MAX(0,(H36-Curtail_Thresh)*Curtail_Rate) -> 0.021794707 | J28: =MAX(0,(I36-Curtail_Thresh)*Curtail_Rate) -> 0.023790995 | K28: =MAX(0,(J36-Curtail_Thresh)*Curtail_Rate) -> 0.026324399 | ... AB28: =MAX(0,(AA36-Curtail_Thresh)*Curtail_Rate) -> 0.074789069
A29: Forward price (logistic-weighted LRMC and spot) | B29: $/MWh | C29: =(1/(1+EXP(-Fwd_k*(C26/C9))))*C22+(1-(1/(1+EXP(-Fwd_k*(C26/C9)))))*C27 -> 112.22814 | D29: =(1/(1+EXP(-Fwd_k*(C26/C9))))*D22+(1-(1/(1+EXP(-Fwd_k*(C26/C9)))))*D27 -> 110.10963 | E29: =(1/(1+EXP(-Fwd_k*(D26/D9))))*E22+(1-(1/(1+EXP(-Fwd_k*(D26/D9)))))*E27 -> 112.52185 | F29: =(1/(1+EXP(-Fwd_k*(E26/E9))))*F22+(1-(1/(1+EXP(-Fwd_k*(E26/E9)))))*F27 -> 97.523344 | G29: =(1/(1+EXP(-Fwd_k*(F26/F9))))*G22+(1-(1/(1+EXP(-Fwd_k*(F26/F9)))))*G27 -> 94.861411 | H29: =(1/(1+EXP(-Fwd_k*(G26/G9))))*H22+(1-(1/(1+EXP(-Fwd_k*(G26/G9)))))*H27 -> 99.808508 | I29: =(1/(1+EXP(-Fwd_k*(H26/H9))))*I22+(1-(1/(1+EXP(-Fwd_k*(H26/H9)))))*I27 -> 95.867408 | J29: =(1/(1+EXP(-Fwd_k*(I26/I9))))*J22+(1-(1/(1+EXP(-Fwd_k*(I26/I9)))))*J27 -> 94.206566 | K29: =(1/(1+EXP(-Fwd_k*(J26/J9))))*K22+(1-(1/(1+EXP(-Fwd_k*(J26/J9)))))*K27 -> 91.569231 | ... AB29: =(1/(1+EXP(-Fwd_k*(AA26/AA9))))*AB22+(1-(1/(1+EXP(-Fwd_k*(AA26/AA9)))))*AB27 -> 76.570744
A30: Firming balance | B30: GW | C30: =C16+C19+C44*Firm_CFp+C23*VRE_ELCC+Other_Firm-C11 -> 3.5348715 | D30: =D16+D19+C44*Firm_CFp+C50*Firm_CFp+D23*VRE_ELCC+Other_Firm-D11 -> 2.677142 | E30: =E16+E19+D44*Firm_CFp+D50*Firm_CFp+E23*VRE_ELCC+Other_Firm-E11 -> 2.2308697 | F30: =F16+F19+E44*Firm_CFp+E50*Firm_CFp+F23*VRE_ELCC+Other_Firm-F11 -> 1.5189257 | G30: =G16+G19+F44*Firm_CFp+F50*Firm_CFp+G23*VRE_ELCC+Other_Firm-G11 -> 0.51832723 | H30: =H16+H19+G44*Firm_CFp+G50*Firm_CFp+H23*VRE_ELCC+Other_Firm-H11 -> -0.23979125 | I30: =I16+I19+H44*Firm_CFp+H50*Firm_CFp+I23*VRE_ELCC+Other_Firm-I11 -> -0.8325328 | J30: =J16+J19+I44*Firm_CFp+I50*Firm_CFp+J23*VRE_ELCC+Other_Firm-J11 -> -1.0954343 | K30: =K16+K19+J44*Firm_CFp+J50*Firm_CFp+K23*VRE_ELCC+Other_Firm-K11 -> -1.6284744 | ... AB30: =AB16+AB19+AA44*Firm_CFp+AA50*Firm_CFp+AB23*VRE_ELCC+Other_Firm-AB11 -> -3.0299645
A31: Firming deficit fraction | B31: — | C31: =MAX(0,-C30/C11) -> 0 | D31: =MAX(0,-D30/D11) -> 0 | E31: =MAX(0,-E30/E11) -> 0 | F31: =MAX(0,-F30/F11) -> 0 | G31: =MAX(0,-G30/G11) -> 0 | H31: =MAX(0,-H30/H11) -> 0.0060329535 | I31: =MAX(0,-I30/I11) -> 0.020535147 | J31: =MAX(0,-J30/J11) -> 0.026490041 | ... AB31: =MAX(0,-AB30/AB11) -> 0.051301581
A32: Scarcity price | B32: $/MWh | C32: =Firm_SRMC*EXP(Firm_Tight*C31) -> 180 | D32: =Firm_SRMC*EXP(Firm_Tight*D31) -> 180 | E32: =Firm_SRMC*EXP(Firm_Tight*E31) -> 180 | F32: =Firm_SRMC*EXP(Firm_Tight*F31) -> 180 | G32: =Firm_SRMC*EXP(Firm_Tight*G31) -> 180 | H32: =Firm_SRMC*EXP(Firm_Tight*H31) -> 183.84117 | I32: =Firm_SRMC*EXP(Firm_Tight*I31) -> 193.4134 | J32: =Firm_SRMC*EXP(Firm_Tight*J31) -> 197.48685 | ... AB32: =Firm_SRMC*EXP(Firm_Tight*AB31) -> 215.40336
A33: MARKET ENTRY
A34: VRE target share of demand (linear ramp to y26) | B34: — | C34: =VRE_Share0+(VRE_ShareT-VRE_Share0)/25*C2 -> 0.383834 | D34: =VRE_Share0+(VRE_ShareT-VRE_Share0)/25*D2 -> 0.40848064 | E34: =VRE_Share0+(VRE_ShareT-VRE_Share0)/25*E2 -> 0.43312728 | F34: =VRE_Share0+(VRE_ShareT-VRE_Share0)/25*F2 -> 0.45777392 | G34: =VRE_Share0+(VRE_ShareT-VRE_Share0)/25*G2 -> 0.48242056 | H34: =VRE_Share0+(VRE_ShareT-VRE_Share0)/25*H2 -> 0.5070672 | I34: =VRE_Share0+(VRE_ShareT-VRE_Share0)/25*I2 -> 0.53171384 | J34: =VRE_Share0+(VRE_ShareT-VRE_Share0)/25*J2 -> 0.55636048 | ... AB34: =VRE_Share0+(VRE_ShareT-VRE_Share0)/25*AB2 -> 1
A35: VRE target capacity (curtailment-adjusted) | B35: GW | C35: =C34*C9/(VRE_CFe*8.76*MAX(1-C28,0.01)) -> 30 | D35: =D34*D9/(VRE_CFe*8.76*MAX(1-D28,0.01)) -> 33.041572 | E35: =E34*E9/(VRE_CFe*8.76*MAX(1-E28,0.01)) -> 35.908746 | F35: =F34*F9/(VRE_CFe*8.76*MAX(1-F28,0.01)) -> 39.248824 | G35: =G34*G9/(VRE_CFe*8.76*MAX(1-G28,0.01)) -> 42.514759 | H35: =H34*H9/(VRE_CFe*8.76*MAX(1-H28,0.01)) -> 45.704454 | I35: =I34*I9/(VRE_CFe*8.76*MAX(1-I28,0.01)) -> 49.268457 | J35: =J34*J9/(VRE_CFe*8.76*MAX(1-J28,0.01)) -> 52.94907 | ... AB35: =AB34*AB9/(VRE_CFe*8.76*MAX(1-AB28,0.01)) -> 156.61512
A36: Current VRE share of demand | B36: — | C36: =C24/C9 -> 0.44780633 | D36: =IF(D9>0,D24/D9,0) -> 0.4473747 | E36: =IF(E9>0,E24/E9,0) -> 0.50590912 | F36: =IF(F9>0,F24/F9,0) -> 0.52418468 | G36: =IF(G9>0,G24/G9,0) -> 0.50997162 | H36: =IF(H9>0,H24/H9,0) -> 0.52913205 | I36: =IF(I9>0,I24/I9,0) -> 0.54244063 | J36: =IF(J9>0,J24/J9,0) -> 0.55932999 | K36: =IF(K9>0,K24/K9,0) -> 0.57883765 | ... AB36: =IF(AB9>0,AB24/AB9,0) -> 0.89701311
A37: Private VRE build — linear supply curve | B37: GW/yr | C37: 2 | D37: =MAX(0,(D29-D22)/VRE_Sprd) -> 1.1876725 | E37: =MAX(0,(E29-E22)/VRE_Sprd) -> 2.755107 | F37: =MAX(0,(F29-F22)/VRE_Sprd) -> 0 | G37: =MAX(0,(G29-G22)/VRE_Sprd) -> 0 | H37: =MAX(0,(H29-H22)/VRE_Sprd) -> 1.9888128 | I37: =MAX(0,(I29-I22)/VRE_Sprd) -> 1.7556157 | J37: =MAX(0,(J29-J22)/VRE_Sprd) -> 1.8578004 | K37: =MAX(0,(K29-K22)/VRE_Sprd) -> 1.7128157 | ... AB37: =MAX(0,(AB29-AB22)/VRE_Sprd) -> 0
A38: ESEM VRE contracted | B38: GW/yr | C38: =IF(ESEM_On*(C2>=ESEM_Start),MAX(0,(C35-B23)),0) -> 0 | D38: =IF(ESEM_On*(D2>=ESEM_Start),MAX(0,(D35-C23)),0) -> 0 | E38: =IF(ESEM_On*(E2>=ESEM_Start),MAX(0,(E35-D23)),0) -> 0 | F38: =IF(ESEM_On*(F2>=ESEM_Start),MAX(0,(F35-E23-(E43-C43))*RE_Cov),0) -> 0 | G38: =IF(ESEM_On*(G2>=ESEM_Start),MIN(MAX(0,(G35-F23-(F43-D43))), ESEM_Build_Cap),0) -> 0 | H38: =IF(ESEM_On*(H2>=ESEM_Start),MIN(MAX(0,(H35-G23-(G43-E43))), ESEM_Build_Cap),0) -> 0.76167405 | I38: =IF(ESEM_On*(I2>=ESEM_Start),MIN(MAX(0,(I35-H23-(H43-F43))), ESEM_Build_Cap),0) -> 0.81351661 | J38: =IF(ESEM_On*(J2>=ESEM_Start),MIN(MAX(0,(J35-I23-(I43-G43))), ESEM_Build_Cap),0) -> 1.1114804 | K38: =IF(ESEM_On*(K2>=ESEM_Start),MIN(MAX(0,(K35-J23-(J43-H43))), ESEM_Build_Cap),0) -> 1.6678602 | L38: =IF(ESEM_On*(L2>=ESEM_Start),MIN(MAX(0,(L35-K23-(K43-I43))), ESEM_Build_Cap),0) -> 1.5072626 | M38: =IF(ESEM_On*(M2>=ESEM_Start),MIN(MAX(0,(M35-L23-(L43-J43))), ESEM_Build_Cap),0) -> 2.3762458 | N38: =IF(ESEM_On*(N2>=ESEM_Start),MIN(MAX(0,(N35-M23-(M43-K43))), ESEM_Build_Cap),0) -> 2.1141849 | ... AB38: =IF(ESEM_On*(AB2>=ESEM_Start),MIN(MAX(0,(AB35-AA23-(AA43-Y43))), ESEM_Build_Cap),0) -> 6
A39: Firming shortfall | B39: GW | C39: =MAX(0,C11-(C16+C19+C23*VRE_ELCC+Other_Firm)) -> 0 | D39: =MAX(0,D11-(D16+D19+C44*Firm_CFp+C50*Firm_CFp+D23*VRE_ELCC+Other_Firm)) -> 0 | E39: =MAX(0,E11-(E16+E19+D44*Firm_CFp+D50*Firm_CFp+E23*VRE_ELCC+Other_Firm)) -> 0 | F39: =MAX(0,F11-(F16+F19+E44*Firm_CFp+E50*Firm_CFp+F23*VRE_ELCC+Other_Firm)) -> 0 | G39: =MAX(0,G11-(G16+G19+F44*Firm_CFp+F50*Firm_CFp+G23*VRE_ELCC+Other_Firm)) -> 0 | H39: =MAX(0,H11-(H16+H19+G44*Firm_CFp+G50*Firm_CFp+H23*VRE_ELCC+Other_Firm)) -> 0.23979125 | I39: =MAX(0,I11-(I16+I19+H44*Firm_CFp+H50*Firm_CFp+I23*VRE_ELCC+Other_Firm)) -> 0.8325328 | J39: =MAX(0,J11-(J16+J19+I44*Firm_CFp+I50*Firm_CFp+J23*VRE_ELCC+Other_Firm)) -> 1.0954343 | K39: =MAX(0,K11-(K16+K19+J44*Firm_CFp+J50*Firm_CFp+K23*VRE_ELCC+Other_Firm)) -> 1.6284744 | ... AB39: =MAX(0,AB11-(AB16+AB19+AA44*Firm_CFp+AA50*Firm_CFp+AB23*VRE_ELCC+Other_Firm)) -> 3.0299645
A40: Private VRE cumulative stock | B40: GW | C40: =C37 -> 2 | D40: =C40*(1-VRE_Dep)+D37 -> 3.1876725 | E40: =D40*(1-VRE_Dep)+E37 -> 5.9427795 | F40: =E40*(1-VRE_Dep)+F37 -> 5.9427795 | G40: =F40*(1-VRE_Dep)+G37 -> 5.9427795 | H40: =G40*(1-VRE_Dep)+H37 -> 7.9315923 | I40: =H40*(1-VRE_Dep)+I37 -> 9.687208 | J40: =I40*(1-VRE_Dep)+J37 -> 11.545008 | K40: =J40*(1-VRE_Dep)+K37 -> 13.257824 | ... AB40: =AA40*(1-VRE_Dep)+AB37 -> 28.450731
A41: ESEM firming contracted | B41: GW/yr | C41: =IF(ESEM_On*(C2>=ESEM_Start),MAX(0,C39*Firm_Cov),0) -> 0 | D41: =IF(ESEM_On*(D2>=ESEM_Start),MAX(0,D39*Firm_Cov),0) -> 0 | E41: =IF(ESEM_On*(E2>=ESEM_Start),MAX(0,E39*Firm_Cov),0) -> 0 | F41: =IF(ESEM_On*(F2>=ESEM_Start),MAX(0,(F39-(E44-C44))*Firm_Cov),0) -> 0 | G41: =IF(ESEM_On*(G2>=ESEM_Start),MAX(0,(G39-(F44-D44))*Firm_Cov),0) -> 0 | H41: =IF(ESEM_On*(H2>=ESEM_Start),MAX(0,(H39-(G44-E44))*Firm_Cov),0) -> 0.21581213 | I41: =IF(ESEM_On*(I2>=ESEM_Start),MAX(0,(I39-(H44-F44))*Firm_Cov),0) -> 0.55504861 | J41: =IF(ESEM_On*(J2>=ESEM_Start),MAX(0,(J39-(I44-G44))*Firm_Cov),0) -> 0.29211621 | K41: =IF(ESEM_On*(K2>=ESEM_Start),MAX(0,(K39-(J44-H44))*Firm_Cov),0) -> 0.70317861 | L41: =IF(ESEM_On*(L2>=ESEM_Start),MAX(0,(L39-(K44-I44))*Firm_Cov),0) -> 0.88977911 | M41: =IF(ESEM_On*(M2>=ESEM_Start),MAX(0,(M39-(L44-J44))*Firm_Cov),0) -> 0.47874248 | ... AB41: =IF(ESEM_On*(AB2>=ESEM_Start),MAX(0,(AB39-(AA44-Y44))*Firm_Cov),0) -> 1.247414
...

Sheet Dashboard
A1: ESEM Model v2 — Dashboard
A2: Key outputs auto-update when Assumptions change. Press F9 to recalculate.
A4: ACTIVE SCENARIO
A5: Scenario number | C5: =Scenario_Num -> 1 | D5: (edit in Assumptions!C4)
A7: Metric | C7: Yr 5 | D7: Yr 10 | E7: Yr 15 | F7: Yr 20
A8: ENERGY SCALE
A9: Demand (TWh) | C9: =Model!G9 -> 198.68632 | D9: =Model!L9 -> 224.79533 | E9: =Model!Q9 -> 254.33529 | F9: =Model!V9 -> 287.75703
A10: ↳ Baseline | C10: =Baseline!H9 -> 198.68632 | D10: =Baseline!M9 -> 224.79533 | E10: =Baseline!R9 -> 254.33529 | F10: =Baseline!W9 -> 287.75703
A11: Coal capacity (GW) | C11: =Model!G14 -> 22 | D11: =Model!L14 -> 21.610282 | E11: =Model!Q14 -> 18.233308 | F11: =Model!V14 -> 13.487847
A12: ↳ Baseline | C12: =Baseline!H14 -> #REF! | D12: =Baseline!M14 -> #REF! | E12: =Baseline!R14 -> #REF! | F12: =Baseline!W14 -> #REF!
A13: VRE online (GW) | C13: =Model!G23 -> 44.94278 | D13: =Model!L23 -> 59.544498 | E13: =Model!Q23 -> 79.839928 | F13: =Model!V23 -> 105.03199
A14: ↳ Baseline | C14: =Baseline!H23 -> #REF! | D14: =Baseline!M23 -> #REF! | E14: =Baseline!R23 -> #REF! | F14: =Baseline!W23 -> #REF!
A16: PRICES
A17: Wholesale $/MWh | C17: =Model!G27 -> 94.58335 | D17: =Model!L27 -> 94.601062 | E17: =Model!Q27 -> 90.036034 | F17: =Model!V27 -> 83.424686
A18: ↳ Baseline | C18: =Baseline!H27 -> #REF! | D18: =Baseline!M27 -> #REF! | E18: =Baseline!R27 -> #REF! | F18: =Baseline!W27 -> #REF!
A19: Forward price $/MWh | C19: =Model!G29 -> 94.861411 | D19: =Model!L29 -> 89.30866 | E19: =Model!Q29 -> 85.136209 | F19: =Model!V29 -> 81.141392
A20: Scarcity $/MWh | C20: =Model!G32 -> 180 | D20: =Model!L32 -> 211.52699 | E20: =Model!Q32 -> 226.55416 | F20: =Model!V32 -> 230.0998
A21: ↳ Baseline | C21: =Baseline!H32 -> #REF! | D21: =Baseline!M32 -> #REF! | E21: =Baseline!R32 -> #REF! | F21: =Baseline!W32 -> #REF!
A22: Consumer price $/MWh | C22: =Model!G64 -> 94.769573 | D22: =Model!L64 -> 94.862914 | E22: =Model!Q64 -> 91.26644 | F22: =Model!V64 -> 85.657127
A23: ↳ Baseline | C23: =Baseline!H65 -> #REF! | D23: =Baseline!M65 -> #REF! | E23: =Baseline!R65 -> #REF! | F23: =Baseline!W65 -> #REF!
A25: ESEM PROCUREMENT
A26: ESEM VRE contracted GW/yr | C26: =Model!G38 -> 0 | D26: =Model!L38 -> 1.5072626 | E26: =Model!Q38 -> 2.5938954 | F26: =Model!V38 -> 3.852049
A27: ESEM firm contracted GW/yr | C27: =Model!G41 -> 0 | D27: =Model!L41 -> 0.88977911 | E27: =Model!Q41 -> 1.4559603 | F27: =Model!V41 -> 1.9235855
A28: ESEM VRE stock (GW) | C28: =Model!G43 -> 0 | D28: =Model!L43 -> 5.8617938 | E28: =Model!Q43 -> 18.611167 | F28: =Model!V43 -> 38.436361
A29: ESEM firm stock (GW) | C29: =Model!G44 -> 0 | D29: =Model!L44 -> 2.6559347 | E29: =Model!Q44 -> 7.2799743 | F29: =Model!V44 -> 12.490068
A30: Private firm build GW/yr | C30: =Model!G49 -> 0 | D30: =Model!L49 -> 0.088419656 | E30: =Model!Q49 -> 0.34547569 | F30: =Model!V49 -> 0.39312401
A31: ↳ Baseline | C31: =Baseline!H50 -> #REF! | D31: =Baseline!M50 -> #REF! | E31: =Baseline!R50 -> #REF! | F31: =Baseline!W50 -> #REF!
A32: Private firm stock (GW) | C32: =Model!G50 -> 0 | D32: =Model!L50 -> 0.088419656 | E32: =Model!Q50 -> 1.3359686 | F32: =Model!V50 -> 2.7902514
A33: ↳ Baseline | C33: =Baseline!H51 -> #REF! | D33: =Baseline!M51 -> #REF! | E33: =Baseline!R51 -> #REF! | F33: =Baseline!W51 -> #REF!
A35: ESEM FISCAL [−ve = cost, +ve = revenue]
A36: VRE recycled (GW/yr) | C36: =Model!G46 -> 0 | D36: =Model!L46 -> 1.5166004 | E36: =Model!Q46 -> 8.7271076 | F36: =Model!V46 -> 19.290594
A37: VRE recycling P&L ($m) | C37: =Model!G48 -> 95.138254 | D37: =Model!L48 -> 92.566046 | E37: =Model!Q48 -> 87.860836 | F37: =Model!V48 -> 86.388529
A38: Firming CfD P&L ($m) | C38: =Model!G52 -> 0 | D38: =Model!L52 -> 190.82388 | E38: =Model!Q52 -> 924.92482 | F38: =Model!V52 -> 1654.2822
A39: Admin cost ($m) | C39: =Model!G59 -> -37 | D39: =Model!L59 -> -37 | E39: =Model!Q59 -> -37 | F39: =Model!V59 -> -37
A40: Net annual P&L ($m) | C40: =Model!G60 -> -37 | D40: =Model!L60 -> -58.863073 | E40: =Model!Q60 -> -312.93576 | F40: =Model!V60 -> -642.40053
A41: Cumulative P&L ($bn) | C41: =Model!G61 -> -0.111 | D41: =Model!L61 -> -0.31786307 | E41: =Model!Q61 -> -1.3606318 | F41: =Model!V61 -> -4.0272831
A42: Levy ($/MWh) | C42: =Model!G62 -> 0.18622319 | D42: =Model!L62 -> 0.26185184 | E42: =Model!Q62 -> 1.2304064 | F42: =Model!V62 -> 2.2324408
A43: Merchant viability | C43: =Model!G65 -> 0.99416739 | D43: =Model!L65 -> 1.1314679 | E43: =Model!Q65 -> 1.1272648 | F43: =Model!V65 -> 1.0589816
A44: ↳ Baseline | C44: =Baseline!H66 -> 0 | D44: =Baseline!M66 -> 0 | E44: =Baseline!R66 -> 0 | F44: =Baseline!W66 -> 0

Sheet Checks
A1: CHECKS — Balance & Constraint Verification
A2: GREEN = pass (within tolerance). RED = fail. Investigate any fail before using outputs.
A3: Check | B3: Tolerance | D3: Yr 1 | E3: Yr 2 | F3: Yr 3 | G3: Yr 4 | H3: Yr 5 | I3: Yr 6 | J3: Yr 7 | K3: Yr 8 | L3: Yr 9 | M3: Yr 10 | N3: Yr 11 | O3: Yr 12 | P3: Yr 13 | Q3: Yr 14 | R3: Yr 15 | S3: Yr 16 | T3: Yr 17 | U3: Yr 18 | V3: Yr 19 | W3: Yr 20 | X3: Yr 21 | Y3: Yr 22 | Z3: Yr 23 | AA3: Yr 24 | AB3: Yr 25 | AC3: Yr 26
A4: Energy balance: supply minus demand (TWh) [should ≈ 0] | B4: 5 | D4: =D15+D24+Other_Gen-D9 -> #REF! | E4: =E15+E24+Other_Gen-E9 -> #REF! | F4: =F15+F24+Other_Gen-F9 -> #REF! | G4: =G15+G24+Other_Gen-G9 -> #REF! | H4: =H15+H24+Other_Gen-H9 -> #REF! | I4: =I15+I24+Other_Gen-I9 -> #REF! | J4: =J15+J24+Other_Gen-J9 -> #REF! | K4: =K15+K24+Other_Gen-K9 -> #REF! | ... AC4: =AC15+AC24+Other_Gen-AC9 -> #REF!
A5: VRE share of demand [should be 0–1] | B5: 0.01 | D5: =MIN(MAX(0,D36),1)-D36 -> 0 | E5: =MIN(MAX(0,E36),1)-E36 -> 0 | F5: =MIN(MAX(0,F36),1)-F36 -> 0 | G5: =MIN(MAX(0,G36),1)-G36 -> 0 | H5: =MIN(MAX(0,H36),1)-H36 -> 0 | I5: =MIN(MAX(0,I36),1)-I36 -> 0 | J5: =MIN(MAX(0,J36),1)-J36 -> 0 | K5: =MIN(MAX(0,K36),1)-K36 -> 0 | ... AC5: =MIN(MAX(0,AC36),1)-AC36 -> 0
A6: Battery weight sum (must = 1) | B6: 0.001 | D6: =Batt_w1h+Batt_w2h+Batt_w4h+Batt_w8h-1 -> 0
A7: Levy consistency: levy×demand minus net cost ($m) [should ≈ 0] | B7: 1 | D7: =D63*D9-D61 -> 0 | E7: =E63*E9-E61 -> 0 | F7: =F63*F9-F61 -> 0 | G7: =G63*G9-G61 -> 0 | H7: =H63*H9-H61 -> 0 | I7: =I63*I9-I61 -> 0 | J7: =J63*J9-J61 -> 0 | K7: =K63*K9-K61 -> 0 | ... AC7: =AC63*AC9-AC61 -> 0
A8: LRMC must be positive ($/MWh) — negative signals BA error | B8: 0 | D8: =MAX(0,-D22) -> 0 | E8: =MAX(0,-E22) -> 0 | F8: =MAX(0,-F22) -> 0 | G8: =MAX(0,-G22) -> 0 | H8: =MAX(0,-H22) -> 0 | I8: =MAX(0,-I22) -> 0 | J8: =MAX(0,-J22) -> 0 | K8: =MAX(0,-K22) -> 0 | ... AC8: =MAX(0,-AC22) -> 0

Sheet Charts
A3: Year | B3: Coal GW | C3: Firm base GW | D3: Exist VRE GW | E3: Priv VRE cum | F3: ESEM VRE cum | G3: ESEM Firm cum | H3: Priv Firm cum | I3: WS_E $/MWh | J3: SC_E $/MWh | K3: Fwd $/MWh | L3: LRMC $/MWh | M3: Consumer_E | N3: Levy $/MWh | O3: NetCost $m | P3: CumCost $bn | Q3: WS/LRMC E | R3: Priv VRE ann | S3: ESEM VRE ann | T3: VRE Online GW | U3: Energy Bal TWh | V3: Settled VRE GW | W3: Settled Firm GW | X3: Firming Bal GW | Y3: WS Baseline | Z3: ESEM VRE ann | AA3: Bline Coal GW | AB3: Bline Firm GW | AC3: Bline PrvVRE GW | AD3: Bline VRE Online | AE3: Bline PrvFirm GW | AF3: Bline Cons Price | AG3: VRE Divest GW | AH3: Firm Divest GW | AI3: Recycle PnL
